2025-10-29 18:49:07,886 - [ ERROR] - handle_exception - 'route'
Traceback (most recent call last):
  File "C:\Users\ocape\AppData\Local\Programs\Python\Python312\Lib\site-packages\nicegui\background_tasks.py", line 93, in _handle_exceptions
    task.result()
  File "C:\Users\ocape\AppData\Local\Programs\Python\Python312\Lib\site-packages\nicegui\functions\navigate.py", line 74, in navigate_sub_pages
    await client.sub_pages_router._handle_navigate(path)  # pylint: disable=protected-access
    ^^^^^^^^^^^^^^^^^^^^^^^^^^^^^^^^^^^^^^^^^^^^^^^^^^^^
  File "C:\Users\ocape\AppData\Local\Programs\Python\Python312\Lib\site-packages\nicegui\sub_pages_router.py", line 68, in _handle_navigate
    not self._other_page_builder_matches_path(path, client)  # `ui.sub_pages` is still responsible
        ^^^^^^^^^^^^^^^^^^^^^^^^^^^^^^^^^^^^^^^^^^^^^^^^^^^
  File "C:\Users\ocape\AppData\Local\Programs\Python\Python312\Lib\site-packages\nicegui\sub_pages_router.py", line 81, in _other_page_builder_matches_path
    client_route = client.request.scope['route']
                   ~~~~~~~~~~~~~~~~~~~~^^^^^^^^^
KeyError: 'route'
2025-10-29 18:49:22,876 - [  INFO] - _execute_sql - SQL: SELECT * FROM users WHERE name='pepa' AND pwd = '123456';
2025-10-29 18:49:22,876 - [  INFO] - login_page - Login ok as admin
2025-10-29 18:49:22,891 - [  INFO] - _execute_sql - SQL: SELECT id, value, status FROM data ORDER BY id;
2025-10-29 18:49:22,891 - [  INFO] - _execute_sql - SQL: SELECT value FROM data WHERE status='ACTIVE' ORDER BY id;
2025-10-29 18:49:22,891 - [  INFO] - get_records_ids - Get 2 ids for status 'ACTIVE
2025-10-29 18:49:22,891 - [ ERROR] - handle_exception - 'route'
Traceback (most recent call last):
  File "C:\Users\ocape\AppData\Local\Programs\Python\Python312\Lib\site-packages\nicegui\background_tasks.py", line 93, in _handle_exceptions
    task.result()
  File "C:\Users\ocape\AppData\Local\Programs\Python\Python312\Lib\site-packages\nicegui\functions\navigate.py", line 74, in navigate_sub_pages
    await client.sub_pages_router._handle_navigate(path)  # pylint: disable=protected-access
    ^^^^^^^^^^^^^^^^^^^^^^^^^^^^^^^^^^^^^^^^^^^^^^^^^^^^
  File "C:\Users\ocape\AppData\Local\Programs\Python\Python312\Lib\site-packages\nicegui\sub_pages_router.py", line 68, in _handle_navigate
    not self._other_page_builder_matches_path(path, client)  # `ui.sub_pages` is still responsible
        ^^^^^^^^^^^^^^^^^^^^^^^^^^^^^^^^^^^^^^^^^^^^^^^^^^^
  File "C:\Users\ocape\AppData\Local\Programs\Python\Python312\Lib\site-packages\nicegui\sub_pages_router.py", line 81, in _other_page_builder_matches_path
    client_route = client.request.scope['route']
                   ~~~~~~~~~~~~~~~~~~~~^^^^^^^^^
KeyError: 'route'
2025-10-29 18:51:31,983 - [ DEBUG] - prune_instances - Pruning stale client 313766fa-2f0e-4b58-b9bb-57b6d1ae43c8
2025-10-29 18:53:23,516 - [  INFO] - <module> - Start application...
2025-10-29 18:53:23,520 - [ DEBUG] - __init__ - Using proactor: IocpProactor
2025-10-29 18:53:24,172 - [  INFO] - _execute_sql - SQL: SELECT id, value, status FROM data ORDER BY id;
2025-10-29 18:53:24,172 - [  INFO] - _execute_sql - SQL: SELECT value FROM data WHERE status='ACTIVE' ORDER BY id;
2025-10-29 18:53:24,173 - [  INFO] - get_records_ids - Get 2 ids for status 'ACTIVE
2025-10-29 19:01:12,296 - [  INFO] - <module> - Start application...
2025-10-29 19:01:12,300 - [ DEBUG] - __init__ - Using proactor: IocpProactor
2025-10-29 19:01:12,974 - [  INFO] - _execute_sql - SQL: SELECT id, value, status FROM data ORDER BY id;
2025-10-29 19:01:12,975 - [  INFO] - _execute_sql - SQL: SELECT value FROM data WHERE status='ACTIVE' ORDER BY id;
2025-10-29 19:01:12,975 - [  INFO] - get_records_ids - Get 2 ids for status 'ACTIVE
2025-10-29 19:01:13,799 - [  INFO] - _execute_sql - SQL: SELECT id, value, status FROM data ORDER BY id;
2025-10-29 19:01:13,801 - [  INFO] - _execute_sql - SQL: SELECT value FROM data WHERE status='ACTIVE' ORDER BY id;
2025-10-29 19:01:13,801 - [  INFO] - get_records_ids - Get 2 ids for status 'ACTIVE
2025-10-29 19:01:16,421 - [ ERROR] - handle_exception - 'route'
Traceback (most recent call last):
  File "C:\Users\ocape\AppData\Local\Programs\Python\Python312\Lib\site-packages\nicegui\events.py", line 433, in wait_for_result
    await result
  File "C:\Users\ocape\AppData\Local\Programs\Python\Python312\Lib\site-packages\nicegui\sub_pages_router.py", line 68, in _handle_navigate
    not self._other_page_builder_matches_path(path, client)  # `ui.sub_pages` is still responsible
        ^^^^^^^^^^^^^^^^^^^^^^^^^^^^^^^^^^^^^^^^^^^^^^^^^^^
  File "C:\Users\ocape\AppData\Local\Programs\Python\Python312\Lib\site-packages\nicegui\sub_pages_router.py", line 81, in _other_page_builder_matches_path
    client_route = client.request.scope['route']
                   ~~~~~~~~~~~~~~~~~~~~^^^^^^^^^
KeyError: 'route'
2025-10-29 19:02:59,064 - [  INFO] - <module> - Start application...
2025-10-29 19:02:59,067 - [ DEBUG] - __init__ - Using proactor: IocpProactor
